2021-11-08 23:44:31,303 INFO: Microblog startup [in /home/shandler/Codigos/microblog/app/__init__.py:46]
2021-11-08 23:55:28,913 INFO: Microblog startup [in /home/shandler/Codigos/microblog/app/__init__.py:46]
2021-11-29 17:54:19,638 INFO: Microblog startup [in C:\Users\Shandler\github\microblog\app\__init__.py:46]
2021-11-29 17:54:50,292 ERROR: Exception on /login [POST] [in C:\Users\Shandler\github\microblog\.venv\lib\site-packages\flask\app.py:1457]
Traceback (most recent call last):
  File "C:\Users\Shandler\github\microblog\.venv\lib\site-packages\sqlalchemy\engine\base.py", line 1802, in _execute_context
    self.dialect.do_execute(
  File "C:\Users\Shandler\github\microblog\.venv\lib\site-packages\sqlalchemy\engine\default.py", line 719, in do_execute
    cursor.execute(statement, parameters)
sqlite3.OperationalError: no such table: user

The above exception was the direct cause of the following exception:

Traceback (most recent call last):
  File "C:\Users\Shandler\github\microblog\.venv\lib\site-packages\flask\app.py", line 2073, in wsgi_app
    response = self.full_dispatch_request()
  File "C:\Users\Shandler\github\microblog\.venv\lib\site-packages\flask\app.py", line 1518, in full_dispatch_request
    rv = self.handle_user_exception(e)
  File "C:\Users\Shandler\github\microblog\.venv\lib\site-packages\flask\app.py", line 1516, in full_dispatch_request
    rv = self.dispatch_request()
  File "C:\Users\Shandler\github\microblog\.venv\lib\site-packages\flask\app.py", line 1502, in dispatch_request
    return self.ensure_sync(self.view_functions[rule.endpoint])(**req.view_args)
  File "C:\Users\Shandler\github\microblog\app\routes.py", line 39, in login
    user = User.query.filter_by(username=form.username.data).first()
  File "C:\Users\Shandler\github\microblog\.venv\lib\site-packages\sqlalchemy\orm\query.py", line 2810, in first
    return self.limit(1)._iter().first()
  File "C:\Users\Shandler\github\microblog\.venv\lib\site-packages\sqlalchemy\orm\query.py", line 2894, in _iter
    result = self.session.execute(
  File "C:\Users\Shandler\github\microblog\.venv\lib\site-packages\sqlalchemy\orm\session.py", line 1689, in execute
    result = conn._execute_20(statement, params or {}, execution_options)
  File "C:\Users\Shandler\github\microblog\.venv\lib\site-packages\sqlalchemy\engine\base.py", line 1614, in _execute_20
    return meth(self, args_10style, kwargs_10style, execution_options)
  File "C:\Users\Shandler\github\microblog\.venv\lib\site-packages\sqlalchemy\sql\elements.py", line 325, in _execute_on_connection
    return connection._execute_clauseelement(
  File "C:\Users\Shandler\github\microblog\.venv\lib\site-packages\sqlalchemy\engine\base.py", line 1481, in _execute_clauseelement
    ret = self._execute_context(
  File "C:\Users\Shandler\github\microblog\.venv\lib\site-packages\sqlalchemy\engine\base.py", line 1845, in _execute_context
    self._handle_dbapi_exception(
  File "C:\Users\Shandler\github\microblog\.venv\lib\site-packages\sqlalchemy\engine\base.py", line 2026, in _handle_dbapi_exception
    util.raise_(
  File "C:\Users\Shandler\github\microblog\.venv\lib\site-packages\sqlalchemy\util\compat.py", line 207, in raise_
    raise exception
  File "C:\Users\Shandler\github\microblog\.venv\lib\site-packages\sqlalchemy\engine\base.py", line 1802, in _execute_context
    self.dialect.do_execute(
  File "C:\Users\Shandler\github\microblog\.venv\lib\site-packages\sqlalchemy\engine\default.py", line 719, in do_execute
    cursor.execute(statement, parameters)
sqlalchemy.exc.OperationalError: (sqlite3.OperationalError) no such table: user
[SQL: SELECT user.id AS user_id, user.username AS user_username, user.email AS user_email, user.password_hash AS user_password_hash, user.about_me AS user_about_me, user.last_seen AS user_last_seen 
FROM user 
WHERE user.username = ?
 LIMIT ? OFFSET ?]
[parameters: ('shandler', 1, 0)]
(Background on this error at: https://sqlalche.me/e/14/e3q8)
2021-11-29 17:55:31,139 ERROR: Exception on /register [POST] [in C:\Users\Shandler\github\microblog\.venv\lib\site-packages\flask\app.py:1457]
Traceback (most recent call last):
  File "C:\Users\Shandler\github\microblog\.venv\lib\site-packages\sqlalchemy\engine\base.py", line 1802, in _execute_context
    self.dialect.do_execute(
  File "C:\Users\Shandler\github\microblog\.venv\lib\site-packages\sqlalchemy\engine\default.py", line 719, in do_execute
    cursor.execute(statement, parameters)
sqlite3.OperationalError: no such table: user

The above exception was the direct cause of the following exception:

Traceback (most recent call last):
  File "C:\Users\Shandler\github\microblog\.venv\lib\site-packages\flask\app.py", line 2073, in wsgi_app
    response = self.full_dispatch_request()
  File "C:\Users\Shandler\github\microblog\.venv\lib\site-packages\flask\app.py", line 1518, in full_dispatch_request
    rv = self.handle_user_exception(e)
  File "C:\Users\Shandler\github\microblog\.venv\lib\site-packages\flask\app.py", line 1516, in full_dispatch_request
    rv = self.dispatch_request()
  File "C:\Users\Shandler\github\microblog\.venv\lib\site-packages\flask\app.py", line 1502, in dispatch_request
    return self.ensure_sync(self.view_functions[rule.endpoint])(**req.view_args)
  File "C:\Users\Shandler\github\microblog\app\routes.py", line 60, in register
    if form.validate_on_submit():
  File "C:\Users\Shandler\github\microblog\.venv\lib\site-packages\flask_wtf\form.py", line 86, in validate_on_submit
    return self.is_submitted() and self.validate()
  File "C:\Users\Shandler\github\microblog\.venv\lib\site-packages\wtforms\form.py", line 329, in validate
    return super().validate(extra)
  File "C:\Users\Shandler\github\microblog\.venv\lib\site-packages\wtforms\form.py", line 146, in validate
    if not field.validate(self, extra):
  File "C:\Users\Shandler\github\microblog\.venv\lib\site-packages\wtforms\fields\core.py", line 242, in validate
    stop_validation = self._run_validation_chain(form, chain)
  File "C:\Users\Shandler\github\microblog\.venv\lib\site-packages\wtforms\fields\core.py", line 262, in _run_validation_chain
    validator(form, self)
  File "C:\Users\Shandler\github\microblog\app\forms.py", line 23, in validate_username
    user = User.query.filter_by(username=username.data).first()
  File "C:\Users\Shandler\github\microblog\.venv\lib\site-packages\sqlalchemy\orm\query.py", line 2810, in first
    return self.limit(1)._iter().first()
  File "C:\Users\Shandler\github\microblog\.venv\lib\site-packages\sqlalchemy\orm\query.py", line 2894, in _iter
    result = self.session.execute(
  File "C:\Users\Shandler\github\microblog\.venv\lib\site-packages\sqlalchemy\orm\session.py", line 1689, in execute
    result = conn._execute_20(statement, params or {}, execution_options)
  File "C:\Users\Shandler\github\microblog\.venv\lib\site-packages\sqlalchemy\engine\base.py", line 1614, in _execute_20
    return meth(self, args_10style, kwargs_10style, execution_options)
  File "C:\Users\Shandler\github\microblog\.venv\lib\site-packages\sqlalchemy\sql\elements.py", line 325, in _execute_on_connection
    return connection._execute_clauseelement(
  File "C:\Users\Shandler\github\microblog\.venv\lib\site-packages\sqlalchemy\engine\base.py", line 1481, in _execute_clauseelement
    ret = self._execute_context(
  File "C:\Users\Shandler\github\microblog\.venv\lib\site-packages\sqlalchemy\engine\base.py", line 1845, in _execute_context
    self._handle_dbapi_exception(
  File "C:\Users\Shandler\github\microblog\.venv\lib\site-packages\sqlalchemy\engine\base.py", line 2026, in _handle_dbapi_exception
    util.raise_(
  File "C:\Users\Shandler\github\microblog\.venv\lib\site-packages\sqlalchemy\util\compat.py", line 207, in raise_
    raise exception
  File "C:\Users\Shandler\github\microblog\.venv\lib\site-packages\sqlalchemy\engine\base.py", line 1802, in _execute_context
    self.dialect.do_execute(
  File "C:\Users\Shandler\github\microblog\.venv\lib\site-packages\sqlalchemy\engine\default.py", line 719, in do_execute
    cursor.execute(statement, parameters)
sqlalchemy.exc.OperationalError: (sqlite3.OperationalError) no such table: user
[SQL: SELECT user.id AS user_id, user.username AS user_username, user.email AS user_email, user.password_hash AS user_password_hash, user.about_me AS user_about_me, user.last_seen AS user_last_seen 
FROM user 
WHERE user.username = ?
 LIMIT ? OFFSET ?]
[parameters: ('Luanna', 1, 0)]
(Background on this error at: https://sqlalche.me/e/14/e3q8)
2021-11-29 18:00:16,591 INFO: Microblog startup [in C:\Users\Shandler\github\microblog\app\__init__.py:46]
2021-11-29 18:00:25,228 INFO: Microblog startup [in C:\Users\Shandler\github\microblog\app\__init__.py:46]
